2024-11-27 07:49:17,878 DEBUG    root            Loaded Command Group: ['gcloud', 'functions']
2024-11-27 07:49:18,954 DEBUG    root            Loaded Command Group: ['gcloud', 'functions', 'deploy']
2024-11-27 07:49:19,032 DEBUG    root            Running [gcloud.functions.deploy] with arguments: [--entry-point: "gcs_trigger", --runtime: "python312", --set-env-vars: "OrderedDict([('PROJECT_ID', 'inspired-photon-441609-k7'), ('TOPIC_ID', 'gcs-trigger-topic')])", --source: "./pubsub_script", --trigger-event: "google.storage.object.finalize", --trigger-resource: "main-bucket-5505", NAME: "gcs-to-pubsub"]
2024-11-27 07:49:19,202 DEBUG    urllib3.connectionpool Starting new HTTPS connection (1): cloudfunctions.googleapis.com:443
2024-11-27 07:49:19,440 DEBUG    urllib3.connectionpool https://cloudfunctions.googleapis.com:443 "GET /v2/projects/inspired-photon-441609-k7/locations/us-central1/functions/gcs-to-pubsub?alt=json HTTP/1.1" 404 None
2024-11-27 07:49:19,443 INFO     ___FILE_ONLY___ As of this Cloud SDK release, new functions will be deployed as 2nd gen  functions by default. This is equivalent to currently deploying new  with the --gen2 flag. Existing 1st gen functions will not be impacted and will continue to deploy as 1st gen functions.
You can disable this behavior by explicitly specifying the --no-gen2 flag or by setting the functions/gen2 config property to 'off'.
To learn more about the differences between 1st gen and 2nd gen functions, visit:
https://cloud.google.com/functions/docs/concepts/version-comparison

2024-11-27 07:49:19,579 DEBUG    urllib3.connectionpool Starting new HTTPS connection (1): cloudfunctions.googleapis.com:443
2024-11-27 07:49:19,737 DEBUG    urllib3.connectionpool https://cloudfunctions.googleapis.com:443 "GET /v2/projects/inspired-photon-441609-k7/locations/us-central1/functions/gcs-to-pubsub?alt=json HTTP/1.1" 404 None
2024-11-27 07:49:19,743 DEBUG    urllib3.connectionpool Starting new HTTPS connection (1): cloudfunctions.googleapis.com:443
2024-11-27 07:49:19,840 DEBUG    urllib3.connectionpool https://cloudfunctions.googleapis.com:443 "GET /v2/projects/inspired-photon-441609-k7/locations/us-central1/runtimes?alt=json HTTP/1.1" 200 None
2024-11-27 07:49:19,901 INFO     root            Not using ignore file.
2024-11-27 07:49:19,926 DEBUG    urllib3.connectionpool Starting new HTTPS connection (1): cloudfunctions.googleapis.com:443
2024-11-27 07:49:20,198 DEBUG    urllib3.connectionpool https://cloudfunctions.googleapis.com:443 "POST /v2/projects/inspired-photon-441609-k7/locations/us-central1/functions:generateUploadUrl?alt=json HTTP/1.1" 200 None
2024-11-27 07:49:20,208 DEBUG    urllib3.connectionpool Starting new HTTPS connection (1): storage.googleapis.com:443
2024-11-27 07:49:20,473 DEBUG    urllib3.connectionpool https://storage.googleapis.com:443 "PUT /gcf-v2-uploads-644941739395.us-central1.cloudfunctions.appspot.com/210058df-ef48-42ee-939e-f8ee26076090.zip?GoogleAccessId=service-644941739395%40gcf-admin-robot.iam.gserviceaccount.com&Expires=1732695560&Signature=cP%2FRQyKw7wkpiRBbpXwtPe6Xv8GezjcwLx9G3fETA9GPTQQWn0i0hGIl232kLXz1BrM36IZi%2Frbcesw%2FZBae67FGySlIpM88tm%2Fw3XkEcWrX0MweleP6n%2FTpLAelaWHfmA00suI7qZHeLTMmJTvbenwNaggGz9ZWf9HgkE9eLF4d959%2F1NFrIWil1nlvMuO3XiiRavHBBp%2BN0pQSDfhWeN3AjUK9XSD4YoomqeRe9%2BL9uhNp4DaHLcNbFD3bll147uUPAB8zDgpua640bypVsNIN1iYNggHV6PqNWDm8sDmFfM4n2sNrmhK1uYZ%2FLeY5VA8SL7UAtmGl1q7%2FtJCIYg%3D%3D HTTP/1.1" 200 0
2024-11-27 07:49:20,555 DEBUG    urllib3.connectionpool Starting new HTTPS connection (1): serviceusage.googleapis.com:443
2024-11-27 07:49:20,732 DEBUG    urllib3.connectionpool https://serviceusage.googleapis.com:443 "GET /v1/projects/inspired-photon-441609-k7/services/run.googleapis.com?alt=json HTTP/1.1" 403 None
2024-11-27 07:49:20,735 INFO     root            Could not verify if service run.googleapis.com is enabled: missing permission 'serviceusage.services.get'.
2024-11-27 07:49:20,802 DEBUG    urllib3.connectionpool Starting new HTTPS connection (1): serviceusage.googleapis.com:443
2024-11-27 07:49:21,030 DEBUG    urllib3.connectionpool https://serviceusage.googleapis.com:443 "GET /v1/projects/inspired-photon-441609-k7/services/cloudbuild.googleapis.com?alt=json HTTP/1.1" 403 None
2024-11-27 07:49:21,032 INFO     root            Could not verify if service cloudbuild.googleapis.com is enabled: missing permission 'serviceusage.services.get'.
2024-11-27 07:49:21,112 DEBUG    urllib3.connectionpool Starting new HTTPS connection (1): serviceusage.googleapis.com:443
2024-11-27 07:49:21,336 DEBUG    urllib3.connectionpool https://serviceusage.googleapis.com:443 "GET /v1/projects/inspired-photon-441609-k7/services/artifactregistry.googleapis.com?alt=json HTTP/1.1" 403 None
2024-11-27 07:49:21,339 INFO     root            Could not verify if service artifactregistry.googleapis.com is enabled: missing permission 'serviceusage.services.get'.
2024-11-27 07:49:21,589 DEBUG    urllib3.connectionpool Starting new HTTPS connection (1): cloudbuild.googleapis.com:443
2024-11-27 07:49:21,719 DEBUG    urllib3.connectionpool https://cloudbuild.googleapis.com:443 "GET /v1/projects/inspired-photon-441609-k7/locations/us-central1/defaultServiceAccount?alt=json HTTP/1.1" 403 None
2024-11-27 07:49:21,722 DEBUG    root            (gcloud.functions.deploy) ResponseError: status=[403], code=[Ok], message=[The caller does not have permission]
Traceback (most recent call last):
  File "/snap/google-cloud-cli/289/lib/googlecloudsdk/api_lib/functions/v1/util.py", line 387, in CatchHTTPErrorRaiseHTTPExceptionFn
    return func(*args, **kwargs)
           ^^^^^^^^^^^^^^^^^^^^^
  File "/snap/google-cloud-cli/289/lib/googlecloudsdk/command_lib/functions/util.py", line 86, in Run
    return self._RunV2(args)
           ^^^^^^^^^^^^^^^^^
  File "/snap/google-cloud-cli/289/lib/surface/functions/deploy.py", line 144, in _RunV2
    return command_v2.Run(args, self.ReleaseTrack())
           ^^^^^^^^^^^^^^^^^^^^^^^^^^^^^^^^^^^^^^^^^
  File "/snap/google-cloud-cli/289/lib/googlecloudsdk/command_lib/functions/v2/deploy/command.py", line 1310, in Run
    service_account_util.ValidateDefaultBuildServiceAccountAndPromptWarning(
  File "/snap/google-cloud-cli/289/lib/googlecloudsdk/command_lib/functions/service_account_util.py", line 63, in ValidateDefaultBuildServiceAccountAndPromptWarning
    GetDefaultBuildServiceAccount(project_id, region)
  File "/snap/google-cloud-cli/289/lib/googlecloudsdk/command_lib/functions/service_account_util.py", line 32, in GetDefaultBuildServiceAccount
    return client.projects_locations.GetDefaultServiceAccount(
           ^^^^^^^^^^^^^^^^^^^^^^^^^^^^^^^^^^^^^^^^^^^^^^^^^^^
  File "/snap/google-cloud-cli/289/lib/googlecloudsdk/generated_clients/apis/cloudbuild/v1/cloudbuild_v1_client.py", line 2473, in GetDefaultServiceAccount
    return self._RunMethod(
           ^^^^^^^^^^^^^^^^
  File "/snap/google-cloud-cli/289/lib/third_party/apitools/base/py/base_api.py", line 747, in _RunMethod
    return self.ProcessHttpResponse(method_config, http_response, request)
           ^^^^^^^^^^^^^^^^^^^^^^^^^^^^^^^^^^^^^^^^^^^^^^^^^^^^^^^^^^^^^^^
  File "/snap/google-cloud-cli/289/lib/third_party/apitools/base/py/base_api.py", line 753, in ProcessHttpResponse
    self.__ProcessHttpResponse(method_config, http_response, request))
    ^^^^^^^^^^^^^^^^^^^^^^^^^^^^^^^^^^^^^^^^^^^^^^^^^^^^^^^^^^^^^^^^^
  File "/snap/google-cloud-cli/289/lib/third_party/apitools/base/py/base_api.py", line 612, in __ProcessHttpResponse
    raise exceptions.HttpError.FromResponse(
apitools.base.py.exceptions.HttpForbiddenError: HttpError accessing <https://cloudbuild.googleapis.com/v1/projects/inspired-photon-441609-k7/locations/us-central1/defaultServiceAccount?alt=json>: response: <{'vary': 'Origin, X-Origin, Referer', 'content-type': 'application/json; charset=UTF-8', 'content-encoding': 'gzip', 'date': 'Wed, 27 Nov 2024 07:49:21 GMT', 'server': 'ESF', 'cache-control': 'private', 'x-xss-protection': '0', 'x-frame-options': 'SAMEORIGIN', 'x-content-type-options': 'nosniff', 'transfer-encoding': 'chunked', 'status': 403}>, content <{
  "error": {
    "code": 403,
    "message": "The caller does not have permission",
    "status": "PERMISSION_DENIED"
  }
}
>

During handling of the above exception, another exception occurred:

Traceback (most recent call last):
  File "/snap/google-cloud-cli/289/lib/googlecloudsdk/calliope/cli.py", line 998, in Execute
    resources = calliope_command.Run(cli=self, args=args)
                ^^^^^^^^^^^^^^^^^^^^^^^^^^^^^^^^^^^^^^^^^
  File "/snap/google-cloud-cli/289/lib/googlecloudsdk/calliope/backend.py", line 843, in Run
    resources = command_instance.Run(args)
                ^^^^^^^^^^^^^^^^^^^^^^^^^^
  File "/snap/google-cloud-cli/289/lib/googlecloudsdk/api_lib/functions/v1/util.py", line 389, in CatchHTTPErrorRaiseHTTPExceptionFn
    core_exceptions.reraise(
  File "/snap/google-cloud-cli/289/lib/googlecloudsdk/core/exceptions.py", line 149, in reraise
    six.reraise(type(exc_value), exc_value, tb)
  File "/snap/google-cloud-cli/289/lib/third_party/six/__init__.py", line 718, in reraise
    raise value.with_traceback(tb)
  File "/snap/google-cloud-cli/289/lib/googlecloudsdk/api_lib/functions/v1/util.py", line 387, in CatchHTTPErrorRaiseHTTPExceptionFn
    return func(*args, **kwargs)
           ^^^^^^^^^^^^^^^^^^^^^
  File "/snap/google-cloud-cli/289/lib/googlecloudsdk/command_lib/functions/util.py", line 86, in Run
    return self._RunV2(args)
           ^^^^^^^^^^^^^^^^^
  File "/snap/google-cloud-cli/289/lib/surface/functions/deploy.py", line 144, in _RunV2
    return command_v2.Run(args, self.ReleaseTrack())
           ^^^^^^^^^^^^^^^^^^^^^^^^^^^^^^^^^^^^^^^^^
  File "/snap/google-cloud-cli/289/lib/googlecloudsdk/command_lib/functions/v2/deploy/command.py", line 1310, in Run
    service_account_util.ValidateDefaultBuildServiceAccountAndPromptWarning(
  File "/snap/google-cloud-cli/289/lib/googlecloudsdk/command_lib/functions/service_account_util.py", line 63, in ValidateDefaultBuildServiceAccountAndPromptWarning
    GetDefaultBuildServiceAccount(project_id, region)
  File "/snap/google-cloud-cli/289/lib/googlecloudsdk/command_lib/functions/service_account_util.py", line 32, in GetDefaultBuildServiceAccount
    return client.projects_locations.GetDefaultServiceAccount(
           ^^^^^^^^^^^^^^^^^^^^^^^^^^^^^^^^^^^^^^^^^^^^^^^^^^^
  File "/snap/google-cloud-cli/289/lib/googlecloudsdk/generated_clients/apis/cloudbuild/v1/cloudbuild_v1_client.py", line 2473, in GetDefaultServiceAccount
    return self._RunMethod(
           ^^^^^^^^^^^^^^^^
  File "/snap/google-cloud-cli/289/lib/third_party/apitools/base/py/base_api.py", line 747, in _RunMethod
    return self.ProcessHttpResponse(method_config, http_response, request)
           ^^^^^^^^^^^^^^^^^^^^^^^^^^^^^^^^^^^^^^^^^^^^^^^^^^^^^^^^^^^^^^^
  File "/snap/google-cloud-cli/289/lib/third_party/apitools/base/py/base_api.py", line 753, in ProcessHttpResponse
    self.__ProcessHttpResponse(method_config, http_response, request))
    ^^^^^^^^^^^^^^^^^^^^^^^^^^^^^^^^^^^^^^^^^^^^^^^^^^^^^^^^^^^^^^^^^
  File "/snap/google-cloud-cli/289/lib/third_party/apitools/base/py/base_api.py", line 612, in __ProcessHttpResponse
    raise exceptions.HttpError.FromResponse(
googlecloudsdk.calliope.exceptions.HttpException: ResponseError: status=[403], code=[Ok], message=[The caller does not have permission]
2024-11-27 07:49:21,759 ERROR    root            (gcloud.functions.deploy) ResponseError: status=[403], code=[Ok], message=[The caller does not have permission]
