2024-11-26 19:17:13,041 DEBUG    root            Loaded Command Group: ['gcloud', 'functions']
2024-11-26 19:17:13,414 DEBUG    root            Loaded Command Group: ['gcloud', 'functions', 'deploy']
2024-11-26 19:17:13,447 DEBUG    root            Running [gcloud.functions.deploy] with arguments: [--entry-point: "gcs_trigger", --runtime: "python312", --set-env-vars: "OrderedDict([('PROJECT_ID', 'inspired-photon-441609-k7'), ('TOPIC_ID', 'gcs-trigger-topic')])", --source: "./pubsub_script", --trigger-event: "google.storage.object.finalize", --trigger-resource: "main-bucket-5505", NAME: "gcs-to-pubsub"]
2024-11-26 19:17:13,611 DEBUG    urllib3.connectionpool Starting new HTTPS connection (1): cloudfunctions.googleapis.com:443
2024-11-26 19:17:13,718 DEBUG    urllib3.connectionpool https://cloudfunctions.googleapis.com:443 "GET /v2/projects/inspired-photon-441609-k7/locations/us-central1/functions/gcs-to-pubsub?alt=json HTTP/1.1" 404 None
2024-11-26 19:17:13,721 INFO     ___FILE_ONLY___ As of this Cloud SDK release, new functions will be deployed as 2nd gen  functions by default. This is equivalent to currently deploying new  with the --gen2 flag. Existing 1st gen functions will not be impacted and will continue to deploy as 1st gen functions.
You can disable this behavior by explicitly specifying the --no-gen2 flag or by setting the functions/gen2 config property to 'off'.
To learn more about the differences between 1st gen and 2nd gen functions, visit:
https://cloud.google.com/functions/docs/concepts/version-comparison

2024-11-26 19:17:13,850 DEBUG    urllib3.connectionpool Starting new HTTPS connection (1): cloudfunctions.googleapis.com:443
2024-11-26 19:17:13,943 DEBUG    urllib3.connectionpool https://cloudfunctions.googleapis.com:443 "GET /v2/projects/inspired-photon-441609-k7/locations/us-central1/functions/gcs-to-pubsub?alt=json HTTP/1.1" 404 None
2024-11-26 19:17:13,948 DEBUG    urllib3.connectionpool Starting new HTTPS connection (1): cloudfunctions.googleapis.com:443
2024-11-26 19:17:14,042 DEBUG    urllib3.connectionpool https://cloudfunctions.googleapis.com:443 "GET /v2/projects/inspired-photon-441609-k7/locations/us-central1/runtimes?alt=json HTTP/1.1" 200 None
2024-11-26 19:17:14,070 INFO     root            Not using ignore file.
2024-11-26 19:17:14,079 DEBUG    urllib3.connectionpool Starting new HTTPS connection (1): cloudfunctions.googleapis.com:443
2024-11-26 19:17:14,226 DEBUG    urllib3.connectionpool https://cloudfunctions.googleapis.com:443 "POST /v2/projects/inspired-photon-441609-k7/locations/us-central1/functions:generateUploadUrl?alt=json HTTP/1.1" 403 None
2024-11-26 19:17:14,231 DEBUG    root            (gcloud.functions.deploy) ResponseError: status=[403], code=[Ok], message=[Permission 'cloudfunctions.functions.generateUploadUrl' denied on 'projects/inspired-photon-441609-k7/locations/us-central1/functions']
Traceback (most recent call last):
  File "/snap/google-cloud-cli/289/lib/googlecloudsdk/api_lib/functions/v1/util.py", line 387, in CatchHTTPErrorRaiseHTTPExceptionFn
    return func(*args, **kwargs)
           ^^^^^^^^^^^^^^^^^^^^^
  File "/snap/google-cloud-cli/289/lib/googlecloudsdk/command_lib/functions/util.py", line 86, in Run
    return self._RunV2(args)
           ^^^^^^^^^^^^^^^^^
  File "/snap/google-cloud-cli/289/lib/surface/functions/deploy.py", line 144, in _RunV2
    return command_v2.Run(args, self.ReleaseTrack())
           ^^^^^^^^^^^^^^^^^^^^^^^^^^^^^^^^^^^^^^^^^
  File "/snap/google-cloud-cli/289/lib/googlecloudsdk/command_lib/functions/v2/deploy/command.py", line 1269, in Run
    build_config, build_updated_fields = _GetBuildConfig(
                                         ^^^^^^^^^^^^^^^^
  File "/snap/google-cloud-cli/289/lib/googlecloudsdk/command_lib/functions/v2/deploy/command.py", line 785, in _GetBuildConfig
    function_source, source_updated_fields = _GetSource(
                                             ^^^^^^^^^^^
  File "/snap/google-cloud-cli/289/lib/googlecloudsdk/command_lib/functions/v2/deploy/command.py", line 316, in _GetSource
    return _GetSourceLocal(
           ^^^^^^^^^^^^^^^^
  File "/snap/google-cloud-cli/289/lib/googlecloudsdk/command_lib/functions/v2/deploy/command.py", line 269, in _GetSourceLocal
    raise e
  File "/snap/google-cloud-cli/289/lib/googlecloudsdk/command_lib/functions/v2/deploy/command.py", line 261, in _GetSourceLocal
    dest = client.projects_locations_functions.GenerateUploadUrl(
           ^^^^^^^^^^^^^^^^^^^^^^^^^^^^^^^^^^^^^^^^^^^^^^^^^^^^^^
  File "/snap/google-cloud-cli/289/lib/googlecloudsdk/generated_clients/apis/cloudfunctions/v2/cloudfunctions_v2_client.py", line 230, in GenerateUploadUrl
    return self._RunMethod(
           ^^^^^^^^^^^^^^^^
  File "/snap/google-cloud-cli/289/lib/third_party/apitools/base/py/base_api.py", line 747, in _RunMethod
    return self.ProcessHttpResponse(method_config, http_response, request)
           ^^^^^^^^^^^^^^^^^^^^^^^^^^^^^^^^^^^^^^^^^^^^^^^^^^^^^^^^^^^^^^^
  File "/snap/google-cloud-cli/289/lib/third_party/apitools/base/py/base_api.py", line 753, in ProcessHttpResponse
    self.__ProcessHttpResponse(method_config, http_response, request))
    ^^^^^^^^^^^^^^^^^^^^^^^^^^^^^^^^^^^^^^^^^^^^^^^^^^^^^^^^^^^^^^^^^
  File "/snap/google-cloud-cli/289/lib/third_party/apitools/base/py/base_api.py", line 612, in __ProcessHttpResponse
    raise exceptions.HttpError.FromResponse(
apitools.base.py.exceptions.HttpForbiddenError: HttpError accessing <https://cloudfunctions.googleapis.com/v2/projects/inspired-photon-441609-k7/locations/us-central1/functions:generateUploadUrl?alt=json>: response: <{'vary': 'Origin, X-Origin, Referer', 'content-type': 'application/json; charset=UTF-8', 'content-encoding': 'gzip', 'date': 'Tue, 26 Nov 2024 19:17:14 GMT', 'server': 'ESF', 'cache-control': 'private', 'x-xss-protection': '0', 'x-frame-options': 'SAMEORIGIN', 'x-content-type-options': 'nosniff', 'transfer-encoding': 'chunked', 'status': 403}>, content <{
  "error": {
    "code": 403,
    "message": "Permission 'cloudfunctions.functions.generateUploadUrl' denied on 'projects/inspired-photon-441609-k7/locations/us-central1/functions'",
    "status": "PERMISSION_DENIED"
  }
}
>

During handling of the above exception, another exception occurred:

Traceback (most recent call last):
  File "/snap/google-cloud-cli/289/lib/googlecloudsdk/calliope/cli.py", line 998, in Execute
    resources = calliope_command.Run(cli=self, args=args)
                ^^^^^^^^^^^^^^^^^^^^^^^^^^^^^^^^^^^^^^^^^
  File "/snap/google-cloud-cli/289/lib/googlecloudsdk/calliope/backend.py", line 843, in Run
    resources = command_instance.Run(args)
                ^^^^^^^^^^^^^^^^^^^^^^^^^^
  File "/snap/google-cloud-cli/289/lib/googlecloudsdk/api_lib/functions/v1/util.py", line 389, in CatchHTTPErrorRaiseHTTPExceptionFn
    core_exceptions.reraise(
  File "/snap/google-cloud-cli/289/lib/googlecloudsdk/core/exceptions.py", line 149, in reraise
    six.reraise(type(exc_value), exc_value, tb)
  File "/snap/google-cloud-cli/289/lib/third_party/six/__init__.py", line 718, in reraise
    raise value.with_traceback(tb)
  File "/snap/google-cloud-cli/289/lib/googlecloudsdk/api_lib/functions/v1/util.py", line 387, in CatchHTTPErrorRaiseHTTPExceptionFn
    return func(*args, **kwargs)
           ^^^^^^^^^^^^^^^^^^^^^
  File "/snap/google-cloud-cli/289/lib/googlecloudsdk/command_lib/functions/util.py", line 86, in Run
    return self._RunV2(args)
           ^^^^^^^^^^^^^^^^^
  File "/snap/google-cloud-cli/289/lib/surface/functions/deploy.py", line 144, in _RunV2
    return command_v2.Run(args, self.ReleaseTrack())
           ^^^^^^^^^^^^^^^^^^^^^^^^^^^^^^^^^^^^^^^^^
  File "/snap/google-cloud-cli/289/lib/googlecloudsdk/command_lib/functions/v2/deploy/command.py", line 1269, in Run
    build_config, build_updated_fields = _GetBuildConfig(
                                         ^^^^^^^^^^^^^^^^
  File "/snap/google-cloud-cli/289/lib/googlecloudsdk/command_lib/functions/v2/deploy/command.py", line 785, in _GetBuildConfig
    function_source, source_updated_fields = _GetSource(
                                             ^^^^^^^^^^^
  File "/snap/google-cloud-cli/289/lib/googlecloudsdk/command_lib/functions/v2/deploy/command.py", line 316, in _GetSource
    return _GetSourceLocal(
           ^^^^^^^^^^^^^^^^
  File "/snap/google-cloud-cli/289/lib/googlecloudsdk/command_lib/functions/v2/deploy/command.py", line 269, in _GetSourceLocal
    raise e
  File "/snap/google-cloud-cli/289/lib/googlecloudsdk/command_lib/functions/v2/deploy/command.py", line 261, in _GetSourceLocal
    dest = client.projects_locations_functions.GenerateUploadUrl(
           ^^^^^^^^^^^^^^^^^^^^^^^^^^^^^^^^^^^^^^^^^^^^^^^^^^^^^^
  File "/snap/google-cloud-cli/289/lib/googlecloudsdk/generated_clients/apis/cloudfunctions/v2/cloudfunctions_v2_client.py", line 230, in GenerateUploadUrl
    return self._RunMethod(
           ^^^^^^^^^^^^^^^^
  File "/snap/google-cloud-cli/289/lib/third_party/apitools/base/py/base_api.py", line 747, in _RunMethod
    return self.ProcessHttpResponse(method_config, http_response, request)
           ^^^^^^^^^^^^^^^^^^^^^^^^^^^^^^^^^^^^^^^^^^^^^^^^^^^^^^^^^^^^^^^
  File "/snap/google-cloud-cli/289/lib/third_party/apitools/base/py/base_api.py", line 753, in ProcessHttpResponse
    self.__ProcessHttpResponse(method_config, http_response, request))
    ^^^^^^^^^^^^^^^^^^^^^^^^^^^^^^^^^^^^^^^^^^^^^^^^^^^^^^^^^^^^^^^^^
  File "/snap/google-cloud-cli/289/lib/third_party/apitools/base/py/base_api.py", line 612, in __ProcessHttpResponse
    raise exceptions.HttpError.FromResponse(
googlecloudsdk.calliope.exceptions.HttpException: ResponseError: status=[403], code=[Ok], message=[Permission 'cloudfunctions.functions.generateUploadUrl' denied on 'projects/inspired-photon-441609-k7/locations/us-central1/functions']
2024-11-26 19:17:14,238 ERROR    root            (gcloud.functions.deploy) ResponseError: status=[403], code=[Ok], message=[Permission 'cloudfunctions.functions.generateUploadUrl' denied on 'projects/inspired-photon-441609-k7/locations/us-central1/functions']
